2023-06-16 15:30:57,638 INFO    StreamThr :14888 [internal.py:wandb_internal():86] W&B internal server running at pid: 14888, started at: 2023-06-16 15:30:57.637744
2023-06-16 15:30:57,641 DEBUG   HandlerThread:14888 [handler.py:handle_request():144] handle_request: status
2023-06-16 15:30:57,643 INFO    WriterThread:14888 [datastore.py:open_for_write():85] open: C:\Users\0005h\OneDrive\Documents\programming\pycharm\Bachelor_thesis\wandb\run-20230616_153057-24rx3ka4\run-24rx3ka4.wandb
2023-06-16 15:30:57,649 DEBUG   SenderThread:14888 [sender.py:send():369] send: header
2023-06-16 15:30:57,717 DEBUG   SenderThread:14888 [sender.py:send():369] send: run
2023-06-16 15:31:01,165 INFO    SenderThread:14888 [retry.py:__call__():172] Retry attempt failed:
Traceback (most recent call last):
  File "C:\Users\0005h\miniconda3\envs\thesis\lib\site-packages\urllib3\connection.py", line 174, in _new_conn
    conn = connection.create_connection(
  File "C:\Users\0005h\miniconda3\envs\thesis\lib\site-packages\urllib3\util\connection.py", line 72, in create_connection
    for res in socket.getaddrinfo(host, port, family, socket.SOCK_STREAM):
  File "C:\Users\0005h\miniconda3\envs\thesis\lib\socket.py", line 955, in getaddrinfo
    for res in _socket.getaddrinfo(host, port, family, type, proto, flags):
socket.gaierror: [Errno 11001] getaddrinfo failed

During handling of the above exception, another exception occurred:

Traceback (most recent call last):
  File "C:\Users\0005h\miniconda3\envs\thesis\lib\site-packages\urllib3\connectionpool.py", line 703, in urlopen
    httplib_response = self._make_request(
  File "C:\Users\0005h\miniconda3\envs\thesis\lib\site-packages\urllib3\connectionpool.py", line 386, in _make_request
    self._validate_conn(conn)
  File "C:\Users\0005h\miniconda3\envs\thesis\lib\site-packages\urllib3\connectionpool.py", line 1042, in _validate_conn
    conn.connect()
  File "C:\Users\0005h\miniconda3\envs\thesis\lib\site-packages\urllib3\connection.py", line 363, in connect
    self.sock = conn = self._new_conn()
  File "C:\Users\0005h\miniconda3\envs\thesis\lib\site-packages\urllib3\connection.py", line 186, in _new_conn
    raise NewConnectionError(
urllib3.exceptions.NewConnectionError: <urllib3.connection.HTTPSConnection object at 0x000001BEE3AF55D0>: Failed to establish a new connection: [Errno 11001] getaddrinfo failed

During handling of the above exception, another exception occurred:

Traceback (most recent call last):
  File "C:\Users\0005h\miniconda3\envs\thesis\lib\site-packages\requests\adapters.py", line 487, in send
    resp = conn.urlopen(
  File "C:\Users\0005h\miniconda3\envs\thesis\lib\site-packages\urllib3\connectionpool.py", line 787, in urlopen
    retries = retries.increment(
  File "C:\Users\0005h\miniconda3\envs\thesis\lib\site-packages\urllib3\util\retry.py", line 592, in increment
    raise MaxRetryError(_pool, url, error or ResponseError(cause))
urllib3.exceptions.MaxRetryError: HTTPSConnectionPool(host='api.wandb.ai', port=443): Max retries exceeded with url: /graphql (Caused by NewConnectionError('<urllib3.connection.HTTPSConnection object at 0x000001BEE3AF55D0>: Failed to establish a new connection: [Errno 11001] getaddrinfo failed'))

During handling of the above exception, another exception occurred:

Traceback (most recent call last):
  File "C:\Users\0005h\miniconda3\envs\thesis\lib\site-packages\wandb\sdk\lib\retry.py", line 131, in __call__
    result = self._call_fn(*args, **kwargs)
  File "C:\Users\0005h\miniconda3\envs\thesis\lib\site-packages\wandb\sdk\internal\internal_api.py", line 320, in execute
    return self.client.execute(*args, **kwargs)  # type: ignore
  File "C:\Users\0005h\miniconda3\envs\thesis\lib\site-packages\wandb\vendor\gql-0.2.0\wandb_gql\client.py", line 52, in execute
    result = self._get_result(document, *args, **kwargs)
  File "C:\Users\0005h\miniconda3\envs\thesis\lib\site-packages\wandb\vendor\gql-0.2.0\wandb_gql\client.py", line 60, in _get_result
    return self.transport.execute(document, *args, **kwargs)
  File "C:\Users\0005h\miniconda3\envs\thesis\lib\site-packages\wandb\sdk\lib\gql_request.py", line 55, in execute
    request = self.session.post(self.url, **post_args)
  File "C:\Users\0005h\miniconda3\envs\thesis\lib\site-packages\requests\sessions.py", line 635, in post
    return self.request("POST", url, data=data, json=json, **kwargs)
  File "C:\Users\0005h\miniconda3\envs\thesis\lib\site-packages\requests\sessions.py", line 587, in request
    resp = self.send(prep, **send_kwargs)
  File "C:\Users\0005h\miniconda3\envs\thesis\lib\site-packages\requests\sessions.py", line 701, in send
    r = adapter.send(request, **kwargs)
  File "C:\Users\0005h\miniconda3\envs\thesis\lib\site-packages\requests\adapters.py", line 520, in send
    raise ConnectionError(e, request=request)
requests.exceptions.ConnectionError: HTTPSConnectionPool(host='api.wandb.ai', port=443): Max retries exceeded with url: /graphql (Caused by NewConnectionError('<urllib3.connection.HTTPSConnection object at 0x000001BEE3AF55D0>: Failed to establish a new connection: [Errno 11001] getaddrinfo failed'))
2023-06-16 15:31:02,764 DEBUG   HandlerThread:14888 [handler.py:handle_request():144] handle_request: keepalive
2023-06-16 15:31:07,813 DEBUG   HandlerThread:14888 [handler.py:handle_request():144] handle_request: keepalive
2023-06-16 15:31:12,868 DEBUG   HandlerThread:14888 [handler.py:handle_request():144] handle_request: keepalive
2023-06-16 15:31:17,922 DEBUG   HandlerThread:14888 [handler.py:handle_request():144] handle_request: keepalive
2023-06-16 15:31:22,971 DEBUG   HandlerThread:14888 [handler.py:handle_request():144] handle_request: keepalive
2023-06-16 15:31:28,039 DEBUG   HandlerThread:14888 [handler.py:handle_request():144] handle_request: keepalive
2023-06-16 15:31:33,103 DEBUG   HandlerThread:14888 [handler.py:handle_request():144] handle_request: keepalive
2023-06-16 15:31:38,139 DEBUG   HandlerThread:14888 [handler.py:handle_request():144] handle_request: keepalive
2023-06-16 15:31:43,197 DEBUG   HandlerThread:14888 [handler.py:handle_request():144] handle_request: keepalive
2023-06-16 15:31:48,244 DEBUG   HandlerThread:14888 [handler.py:handle_request():144] handle_request: keepalive
2023-06-16 15:31:53,303 DEBUG   HandlerThread:14888 [handler.py:handle_request():144] handle_request: keepalive
2023-06-16 15:31:58,358 DEBUG   HandlerThread:14888 [handler.py:handle_request():144] handle_request: cancel
2023-06-16 15:31:58,360 DEBUG   HandlerThread:14888 [handler.py:handle_request():144] handle_request: cancel
2023-06-16 15:31:58,416 DEBUG   HandlerThread:14888 [handler.py:handle_request():144] handle_request: shutdown
2023-06-16 15:31:58,417 INFO    HandlerThread:14888 [handler.py:finish():854] shutting down handler
2023-06-16 15:31:59,364 INFO    WriterThread:14888 [datastore.py:close():298] close: C:\Users\0005h\OneDrive\Documents\programming\pycharm\Bachelor_thesis\wandb\run-20230616_153057-24rx3ka4\run-24rx3ka4.wandb
2023-06-16 15:32:07,695 DEBUG   SenderThread:14888 [sender.py:send():378] Record cancelled: run
2023-06-16 15:32:07,696 INFO    SenderThread:14888 [sender.py:finish():1526] shutting down sender
