2023-06-21 03:36:06,152 INFO    Thread-21 (_run_job):21568 [wandb_setup.py:_flush():76] Current SDK version is 0.15.4
2023-06-21 03:36:06,153 INFO    Thread-21 (_run_job):21568 [wandb_setup.py:_flush():76] Configure stats pid to 21568
2023-06-21 03:36:06,153 INFO    Thread-21 (_run_job):21568 [wandb_setup.py:_flush():76] Loading settings from C:\Users\0005h\.config\wandb\settings
2023-06-21 03:36:06,153 INFO    Thread-21 (_run_job):21568 [wandb_setup.py:_flush():76] Loading settings from C:\Users\0005h\OneDrive\Documents\programming\pycharm\Bachelor_thesis\wandb\settings
2023-06-21 03:36:06,154 INFO    Thread-21 (_run_job):21568 [wandb_setup.py:_flush():76] Loading settings from environment variables: {'project': 'sweep_1', 'entity': 'korytheholy', 'root_dir': 'C:\\Users\\0005h\\OneDrive\\Documents\\programming\\pycharm\\Bachelor_thesis', 'run_id': 'yqtte3yy', 'sweep_param_path': 'C:\\Users\\0005h\\OneDrive\\Documents\\programming\\pycharm\\Bachelor_thesis\\wandb\\sweep-xzvb586t\\config-yqtte3yy.yaml', 'sweep_id': 'xzvb586t'}
2023-06-21 03:36:06,164 INFO    Thread-21 (_run_job):21568 [wandb_setup.py:_flush():76] Applying setup settings: {'_disable_service': False}
2023-06-21 03:36:06,164 INFO    Thread-21 (_run_job):21568 [wandb_setup.py:_flush():76] Inferring run settings from compute environment: {'program_relpath': 'train_bbox.py', 'program': 'C:\\Users\\0005h\\OneDrive\\Documents\\programming\\pycharm\\Bachelor_thesis\\train_bbox.py'}
2023-06-21 03:36:06,166 INFO    Thread-21 (_run_job):21568 [wandb_init.py:_log_setup():507] Logging user logs to C:\Users\0005h\OneDrive\Documents\programming\pycharm\Bachelor_thesis\wandb\run-20230621_033606-yqtte3yy\logs\debug.log
2023-06-21 03:36:06,166 INFO    Thread-21 (_run_job):21568 [wandb_init.py:_log_setup():508] Logging internal logs to C:\Users\0005h\OneDrive\Documents\programming\pycharm\Bachelor_thesis\wandb\run-20230621_033606-yqtte3yy\logs\debug-internal.log
2023-06-21 03:36:06,167 INFO    Thread-21 (_run_job):21568 [wandb_init.py:init():547] calling init triggers
2023-06-21 03:36:06,167 INFO    Thread-21 (_run_job):21568 [wandb_init.py:init():554] wandb.init called with sweep_config: {'base_dim': 32, 'batch_norm': True, 'batch_size': 11, 'dropout': 0.4, 'loss_type': 'general_iou', 'lr': 1.31607198495446e-06}
config: {'batch_size': 20, 'lr': 1e-07, 'base_dim': 64, 'dropout': 0.2, 'batch_norm': True, 'loss_type': 'complete_iou'}
2023-06-21 03:36:06,167 INFO    Thread-21 (_run_job):21568 [wandb_init.py:init():596] starting backend
2023-06-21 03:36:06,167 INFO    Thread-21 (_run_job):21568 [wandb_init.py:init():600] setting up manager
2023-06-21 03:36:06,222 INFO    Thread-21 (_run_job):21568 [backend.py:_multiprocessing_setup():106] multiprocessing start_methods=spawn, using: spawn
2023-06-21 03:36:06,249 INFO    Thread-21 (_run_job):21568 [wandb_init.py:init():606] backend started and connected
2023-06-21 03:36:06,282 INFO    Thread-21 (_run_job):21568 [wandb_run.py:_config_callback():1283] config_cb None None {'base_dim': 32, 'batch_norm': True, 'batch_size': 11, 'dropout': 0.4, 'loss_type': 'general_iou', 'lr': 1.31607198495446e-06}
2023-06-21 03:36:06,286 INFO    Thread-21 (_run_job):21568 [wandb_init.py:init():703] updated telemetry
2023-06-21 03:36:06,451 INFO    Thread-21 (_run_job):21568 [wandb_init.py:init():736] communicating run to backend with 60.0 second timeout
2023-06-21 03:36:07,584 INFO    Thread-21 (_run_job):21568 [wandb_run.py:_on_init():2176] communicating current version
2023-06-21 03:36:07,799 INFO    Thread-21 (_run_job):21568 [wandb_run.py:_on_init():2185] got version response 
2023-06-21 03:36:07,800 INFO    Thread-21 (_run_job):21568 [wandb_init.py:init():787] starting run threads in backend
2023-06-21 03:36:08,895 INFO    Thread-21 (_run_job):21568 [wandb_run.py:_console_start():2155] atexit reg
2023-06-21 03:36:08,896 INFO    Thread-21 (_run_job):21568 [wandb_run.py:_redirect():2010] redirect: SettingsConsole.WRAP_RAW
2023-06-21 03:36:08,897 INFO    Thread-21 (_run_job):21568 [wandb_run.py:_redirect():2075] Wrapping output streams.
2023-06-21 03:36:08,898 INFO    Thread-21 (_run_job):21568 [wandb_run.py:_redirect():2100] Redirects installed.
2023-06-21 03:36:08,905 INFO    Thread-21 (_run_job):21568 [wandb_init.py:init():828] run started, returning control to user process
2023-06-21 03:36:09,291 INFO    Thread-21 (_run_job):21568 [wandb_watch.py:watch():51] Watching
2023-06-21 03:38:09,288 INFO    Thread-8 (_heartbeat):21568 [retry.py:__call__():172] Retry attempt failed:
Traceback (most recent call last):
  File "C:\Users\0005h\miniconda3\envs\thesis\lib\site-packages\urllib3\connection.py", line 174, in _new_conn
    conn = connection.create_connection(
  File "C:\Users\0005h\miniconda3\envs\thesis\lib\site-packages\urllib3\util\connection.py", line 72, in create_connection
    for res in socket.getaddrinfo(host, port, family, socket.SOCK_STREAM):
  File "C:\Users\0005h\miniconda3\envs\thesis\lib\socket.py", line 955, in getaddrinfo
    for res in _socket.getaddrinfo(host, port, family, type, proto, flags):
socket.gaierror: [Errno 11001] getaddrinfo failed

During handling of the above exception, another exception occurred:

Traceback (most recent call last):
  File "C:\Users\0005h\miniconda3\envs\thesis\lib\site-packages\urllib3\connectionpool.py", line 714, in urlopen
    httplib_response = self._make_request(
  File "C:\Users\0005h\miniconda3\envs\thesis\lib\site-packages\urllib3\connectionpool.py", line 403, in _make_request
    self._validate_conn(conn)
  File "C:\Users\0005h\miniconda3\envs\thesis\lib\site-packages\urllib3\connectionpool.py", line 1053, in _validate_conn
    conn.connect()
  File "C:\Users\0005h\miniconda3\envs\thesis\lib\site-packages\urllib3\connection.py", line 363, in connect
    self.sock = conn = self._new_conn()
  File "C:\Users\0005h\miniconda3\envs\thesis\lib\site-packages\urllib3\connection.py", line 186, in _new_conn
    raise NewConnectionError(
urllib3.exceptions.NewConnectionError: <urllib3.connection.HTTPSConnection object at 0x00000154ACCE10F0>: Failed to establish a new connection: [Errno 11001] getaddrinfo failed

During handling of the above exception, another exception occurred:

Traceback (most recent call last):
  File "C:\Users\0005h\miniconda3\envs\thesis\lib\site-packages\requests\adapters.py", line 487, in send
    resp = conn.urlopen(
  File "C:\Users\0005h\miniconda3\envs\thesis\lib\site-packages\urllib3\connectionpool.py", line 798, in urlopen
    retries = retries.increment(
  File "C:\Users\0005h\miniconda3\envs\thesis\lib\site-packages\urllib3\util\retry.py", line 592, in increment
    raise MaxRetryError(_pool, url, error or ResponseError(cause))
urllib3.exceptions.MaxRetryError: HTTPSConnectionPool(host='api.wandb.ai', port=443): Max retries exceeded with url: /graphql (Caused by NewConnectionError('<urllib3.connection.HTTPSConnection object at 0x00000154ACCE10F0>: Failed to establish a new connection: [Errno 11001] getaddrinfo failed'))

During handling of the above exception, another exception occurred:

Traceback (most recent call last):
  File "C:\Users\0005h\miniconda3\envs\thesis\lib\site-packages\wandb\sdk\lib\retry.py", line 131, in __call__
    result = self._call_fn(*args, **kwargs)
  File "C:\Users\0005h\miniconda3\envs\thesis\lib\site-packages\wandb\sdk\internal\internal_api.py", line 320, in execute
    return self.client.execute(*args, **kwargs)  # type: ignore
  File "C:\Users\0005h\miniconda3\envs\thesis\lib\site-packages\wandb\vendor\gql-0.2.0\wandb_gql\client.py", line 52, in execute
    result = self._get_result(document, *args, **kwargs)
  File "C:\Users\0005h\miniconda3\envs\thesis\lib\site-packages\wandb\vendor\gql-0.2.0\wandb_gql\client.py", line 60, in _get_result
    return self.transport.execute(document, *args, **kwargs)
  File "C:\Users\0005h\miniconda3\envs\thesis\lib\site-packages\wandb\sdk\lib\gql_request.py", line 55, in execute
    request = self.session.post(self.url, **post_args)
  File "C:\Users\0005h\miniconda3\envs\thesis\lib\site-packages\requests\sessions.py", line 635, in post
    return self.request("POST", url, data=data, json=json, **kwargs)
  File "C:\Users\0005h\miniconda3\envs\thesis\lib\site-packages\requests\sessions.py", line 587, in request
    resp = self.send(prep, **send_kwargs)
  File "C:\Users\0005h\miniconda3\envs\thesis\lib\site-packages\requests\sessions.py", line 701, in send
    r = adapter.send(request, **kwargs)
  File "C:\Users\0005h\miniconda3\envs\thesis\lib\site-packages\requests\adapters.py", line 520, in send
    raise ConnectionError(e, request=request)
requests.exceptions.ConnectionError: HTTPSConnectionPool(host='api.wandb.ai', port=443): Max retries exceeded with url: /graphql (Caused by NewConnectionError('<urllib3.connection.HTTPSConnection object at 0x00000154ACCE10F0>: Failed to establish a new connection: [Errno 11001] getaddrinfo failed'))
2023-06-21 03:40:35,510 INFO    Thread-21 (_run_job):21568 [wandb_run.py:_finish():1890] finishing run korytheholy/sweep_1/yqtte3yy
2023-06-21 03:40:35,510 INFO    Thread-21 (_run_job):21568 [wandb_run.py:_atexit_cleanup():2124] got exitcode: 0
2023-06-21 03:40:35,511 INFO    Thread-21 (_run_job):21568 [wandb_run.py:_restore():2107] restore
2023-06-21 03:40:35,511 INFO    Thread-21 (_run_job):21568 [wandb_run.py:_restore():2113] restore done
2023-06-21 03:40:42,027 INFO    Thread-21 (_run_job):21568 [wandb_run.py:_footer_history_summary_info():3467] rendering history
2023-06-21 03:40:42,034 INFO    Thread-21 (_run_job):21568 [wandb_run.py:_footer_history_summary_info():3499] rendering summary
2023-06-21 03:40:42,048 INFO    Thread-21 (_run_job):21568 [wandb_run.py:_footer_sync_info():3426] logging synced files
